<?xml version="1.0" ?>
<!-- =================================================================================== -->
<!-- |    This document was autogenerated by xacro from /home/robostep/nav2-sample/src/OpenBase/openbase_gazebo_models/models/primitive_omni_wheel/model.sdf.xacro | -->
<!-- |    EDITING THIS FILE BY HAND IS NOT RECOMMENDED                                 | -->
<!-- =================================================================================== -->
<sdf version="1.7">
  <!--
	<xacro:property name="omni_wheel_params" value="${
		xacro.dotify(dict(
			rim_radius=0.018, rim_length=0.01,
			roller_radius=0.0049, roller_length=0.01,
			rim_inner_radius=0.01355, rim_inner_length=0.0055,
			rim_mass=0.00835758, roller_mass=0.00313845,
			num_rollers=4
		)) }"/>
	-->
  <!--
	<xacro:property name="omni_wheel_params" value="${
		xacro.dotify(dict(
			rim_radius=0.06, rim_length=0.025,
			roller_radius=0.008, roller_length=0.020,
			rim_inner_radius=0.055, rim_inner_length=0.008,
			rim_mass=0.30, roller_mass=0.01,
			num_rollers=8
		)) }"/>
	-->
  <!--
	<xacro:property name="omni_wheel_params" value="${
		xacro.dotify(dict(
			rim_radius=0.06, rim_length=0.025,
			roller_radius=0.008, roller_length=0.010,
			rim_inner_radius=0.055, rim_inner_length=0.008,
			rim_mass=0.30, roller_mass=0.01,
			num_rollers=16
		)) }"/>
	-->
  <model name="primitive_omni_wheel_model">
    <pose>0 0 0.1 0 0 0</pose>
    <link name="rim_link">
      <pose>0 0 0 1.5707963267948966 0 0</pose>
      <inertial>
        <mass>0.3</mass>
        <inertia>
          <ixx>0.000291025</ixx>
          <ixy>0</ixy>
          <ixz>0</ixz>
          <iyy>0.000291025</iyy>
          <iyz>0</iyz>
          <izz>0.00054</izz>
        </inertia>
      </inertial>
      <visual name="visual">
        <geometry>
          <cylinder>
            <radius>0.06</radius>
            <length>0.029</length>
          </cylinder>
        </geometry>
        <material>
          <script>
            <uri>file://media/materials/scripts/gazebo.material</uri>
            <name>Gazebo/Grey</name>
          </script>
        </material>
      </visual>
      <collision name="collision">
        <geometry>
          <cylinder>
            <radius>0.06</radius>
            <length>0.029</length>
          </cylinder>
        </geometry>
        <surface>
          <friction>
            <ode>
              <mu>1</mu>
              <mu2>1</mu2>
              <fdir1>0 0 0</fdir1>
              <slip1>0</slip1>
              <slip2>0</slip2>
            </ode>
          </friction>
        </surface>
      </collision>
    </link>
    <link name="roller_link_0_0">
      <pose>0.05 0.008 0.0 0 -0.0 0</pose>
      <inertial>
        <mass>0.03</mass>
        <inertia>
          <ixx>3.5027999999999997e-06</ixx>
          <ixy>0</ixy>
          <ixz>0</ixz>
          <iyy>3.5027999999999997e-06</iyy>
          <iyz>0</iyz>
          <izz>2.5055999999999998e-06</izz>
        </inertia>
      </inertial>
      <visual name="visual">
        <geometry>
          <cylinder>
            <radius>0.012</radius>
            <length>0.03</length>
          </cylinder>
        </geometry>
        <material>
          <script>
            <uri>file://media/materials/scripts/gazebo.material</uri>
            <name>Gazebo/Black</name>
          </script>
        </material>
      </visual>
      <collision name="collision">
        <geometry>
          <cylinder>
            <radius>0.012</radius>
            <length>0.03</length>
          </cylinder>
        </geometry>
        <surface>
          <friction>
            <ode>
              <mu>1</mu>
              <mu2>1</mu2>
              <fdir1>0 0 0</fdir1>
              <slip1>0</slip1>
              <slip2>0</slip2>
            </ode>
          </friction>
        </surface>
      </collision>
    </link>
    <joint name="omni_wheel_joint_0_0" type="revolute">
      <parent>rim_link</parent>
      <child>roller_link_0_0</child>
      <axis>
        <xyz>0 0 1</xyz>
        <dynamics>
          <spring_reference>0</spring_reference>
          <spring_stiffness>0</spring_stiffness>
          <damping>0</damping>
          <friction>0.001</friction>
        </dynamics>
      </axis>
    </joint>
    <link name="roller_link_1_0">
      <pose>0.03535533905932738 -0.008 0.035355339059327376 0 -0.7853981633974483 0</pose>
      <inertial>
        <mass>0.03</mass>
        <inertia>
          <ixx>3.5027999999999997e-06</ixx>
          <ixy>0</ixy>
          <ixz>0</ixz>
          <iyy>3.5027999999999997e-06</iyy>
          <iyz>0</iyz>
          <izz>2.5055999999999998e-06</izz>
        </inertia>
      </inertial>
      <visual name="visual">
        <geometry>
          <cylinder>
            <radius>0.012</radius>
            <length>0.03</length>
          </cylinder>
        </geometry>
        <material>
          <script>
            <uri>file://media/materials/scripts/gazebo.material</uri>
            <name>Gazebo/Black</name>
          </script>
        </material>
      </visual>
      <collision name="collision">
        <geometry>
          <cylinder>
            <radius>0.012</radius>
            <length>0.03</length>
          </cylinder>
        </geometry>
        <surface>
          <friction>
            <ode>
              <mu>1</mu>
              <mu2>1</mu2>
              <fdir1>0 0 0</fdir1>
              <slip1>0</slip1>
              <slip2>0</slip2>
            </ode>
          </friction>
        </surface>
      </collision>
    </link>
    <joint name="omni_wheel_joint_1_0" type="revolute">
      <parent>rim_link</parent>
      <child>roller_link_1_0</child>
      <axis>
        <xyz>0 0 1</xyz>
        <dynamics>
          <spring_reference>0</spring_reference>
          <spring_stiffness>0</spring_stiffness>
          <damping>0</damping>
          <friction>0.001</friction>
        </dynamics>
      </axis>
    </joint>
    <link name="roller_link_0_1">
      <pose>3.061616997868383e-18 0.008 0.05 0 -1.5707963267948966 0</pose>
      <inertial>
        <mass>0.03</mass>
        <inertia>
          <ixx>3.5027999999999997e-06</ixx>
          <ixy>0</ixy>
          <ixz>0</ixz>
          <iyy>3.5027999999999997e-06</iyy>
          <iyz>0</iyz>
          <izz>2.5055999999999998e-06</izz>
        </inertia>
      </inertial>
      <visual name="visual">
        <geometry>
          <cylinder>
            <radius>0.012</radius>
            <length>0.03</length>
          </cylinder>
        </geometry>
        <material>
          <script>
            <uri>file://media/materials/scripts/gazebo.material</uri>
            <name>Gazebo/Black</name>
          </script>
        </material>
      </visual>
      <collision name="collision">
        <geometry>
          <cylinder>
            <radius>0.012</radius>
            <length>0.03</length>
          </cylinder>
        </geometry>
        <surface>
          <friction>
            <ode>
              <mu>1</mu>
              <mu2>1</mu2>
              <fdir1>0 0 0</fdir1>
              <slip1>0</slip1>
              <slip2>0</slip2>
            </ode>
          </friction>
        </surface>
      </collision>
    </link>
    <joint name="omni_wheel_joint_0_1" type="revolute">
      <parent>rim_link</parent>
      <child>roller_link_0_1</child>
      <axis>
        <xyz>0 0 1</xyz>
        <dynamics>
          <spring_reference>0</spring_reference>
          <spring_stiffness>0</spring_stiffness>
          <damping>0</damping>
          <friction>0.001</friction>
        </dynamics>
      </axis>
    </joint>
    <link name="roller_link_1_1">
      <pose>-0.035355339059327376 -0.008 0.03535533905932738 0 -2.356194490192345 0</pose>
      <inertial>
        <mass>0.03</mass>
        <inertia>
          <ixx>3.5027999999999997e-06</ixx>
          <ixy>0</ixy>
          <ixz>0</ixz>
          <iyy>3.5027999999999997e-06</iyy>
          <iyz>0</iyz>
          <izz>2.5055999999999998e-06</izz>
        </inertia>
      </inertial>
      <visual name="visual">
        <geometry>
          <cylinder>
            <radius>0.012</radius>
            <length>0.03</length>
          </cylinder>
        </geometry>
        <material>
          <script>
            <uri>file://media/materials/scripts/gazebo.material</uri>
            <name>Gazebo/Black</name>
          </script>
        </material>
      </visual>
      <collision name="collision">
        <geometry>
          <cylinder>
            <radius>0.012</radius>
            <length>0.03</length>
          </cylinder>
        </geometry>
        <surface>
          <friction>
            <ode>
              <mu>1</mu>
              <mu2>1</mu2>
              <fdir1>0 0 0</fdir1>
              <slip1>0</slip1>
              <slip2>0</slip2>
            </ode>
          </friction>
        </surface>
      </collision>
    </link>
    <joint name="omni_wheel_joint_1_1" type="revolute">
      <parent>rim_link</parent>
      <child>roller_link_1_1</child>
      <axis>
        <xyz>0 0 1</xyz>
        <dynamics>
          <spring_reference>0</spring_reference>
          <spring_stiffness>0</spring_stiffness>
          <damping>0</damping>
          <friction>0.001</friction>
        </dynamics>
      </axis>
    </joint>
    <link name="roller_link_0_2">
      <pose>-0.05 0.008 6.123233995736766e-18 0 -3.141592653589793 0</pose>
      <inertial>
        <mass>0.03</mass>
        <inertia>
          <ixx>3.5027999999999997e-06</ixx>
          <ixy>0</ixy>
          <ixz>0</ixz>
          <iyy>3.5027999999999997e-06</iyy>
          <iyz>0</iyz>
          <izz>2.5055999999999998e-06</izz>
        </inertia>
      </inertial>
      <visual name="visual">
        <geometry>
          <cylinder>
            <radius>0.012</radius>
            <length>0.03</length>
          </cylinder>
        </geometry>
        <material>
          <script>
            <uri>file://media/materials/scripts/gazebo.material</uri>
            <name>Gazebo/Black</name>
          </script>
        </material>
      </visual>
      <collision name="collision">
        <geometry>
          <cylinder>
            <radius>0.012</radius>
            <length>0.03</length>
          </cylinder>
        </geometry>
        <surface>
          <friction>
            <ode>
              <mu>1</mu>
              <mu2>1</mu2>
              <fdir1>0 0 0</fdir1>
              <slip1>0</slip1>
              <slip2>0</slip2>
            </ode>
          </friction>
        </surface>
      </collision>
    </link>
    <joint name="omni_wheel_joint_0_2" type="revolute">
      <parent>rim_link</parent>
      <child>roller_link_0_2</child>
      <axis>
        <xyz>0 0 1</xyz>
        <dynamics>
          <spring_reference>0</spring_reference>
          <spring_stiffness>0</spring_stiffness>
          <damping>0</damping>
          <friction>0.001</friction>
        </dynamics>
      </axis>
    </joint>
    <link name="roller_link_1_2">
      <pose>-0.03535533905932738 -0.008 -0.035355339059327376 0 -3.9269908169872414 0</pose>
      <inertial>
        <mass>0.03</mass>
        <inertia>
          <ixx>3.5027999999999997e-06</ixx>
          <ixy>0</ixy>
          <ixz>0</ixz>
          <iyy>3.5027999999999997e-06</iyy>
          <iyz>0</iyz>
          <izz>2.5055999999999998e-06</izz>
        </inertia>
      </inertial>
      <visual name="visual">
        <geometry>
          <cylinder>
            <radius>0.012</radius>
            <length>0.03</length>
          </cylinder>
        </geometry>
        <material>
          <script>
            <uri>file://media/materials/scripts/gazebo.material</uri>
            <name>Gazebo/Black</name>
          </script>
        </material>
      </visual>
      <collision name="collision">
        <geometry>
          <cylinder>
            <radius>0.012</radius>
            <length>0.03</length>
          </cylinder>
        </geometry>
        <surface>
          <friction>
            <ode>
              <mu>1</mu>
              <mu2>1</mu2>
              <fdir1>0 0 0</fdir1>
              <slip1>0</slip1>
              <slip2>0</slip2>
            </ode>
          </friction>
        </surface>
      </collision>
    </link>
    <joint name="omni_wheel_joint_1_2" type="revolute">
      <parent>rim_link</parent>
      <child>roller_link_1_2</child>
      <axis>
        <xyz>0 0 1</xyz>
        <dynamics>
          <spring_reference>0</spring_reference>
          <spring_stiffness>0</spring_stiffness>
          <damping>0</damping>
          <friction>0.001</friction>
        </dynamics>
      </axis>
    </joint>
    <link name="roller_link_0_3">
      <pose>-9.184850993605149e-18 0.008 -0.05 0 -4.71238898038469 0</pose>
      <inertial>
        <mass>0.03</mass>
        <inertia>
          <ixx>3.5027999999999997e-06</ixx>
          <ixy>0</ixy>
          <ixz>0</ixz>
          <iyy>3.5027999999999997e-06</iyy>
          <iyz>0</iyz>
          <izz>2.5055999999999998e-06</izz>
        </inertia>
      </inertial>
      <visual name="visual">
        <geometry>
          <cylinder>
            <radius>0.012</radius>
            <length>0.03</length>
          </cylinder>
        </geometry>
        <material>
          <script>
            <uri>file://media/materials/scripts/gazebo.material</uri>
            <name>Gazebo/Black</name>
          </script>
        </material>
      </visual>
      <collision name="collision">
        <geometry>
          <cylinder>
            <radius>0.012</radius>
            <length>0.03</length>
          </cylinder>
        </geometry>
        <surface>
          <friction>
            <ode>
              <mu>1</mu>
              <mu2>1</mu2>
              <fdir1>0 0 0</fdir1>
              <slip1>0</slip1>
              <slip2>0</slip2>
            </ode>
          </friction>
        </surface>
      </collision>
    </link>
    <joint name="omni_wheel_joint_0_3" type="revolute">
      <parent>rim_link</parent>
      <child>roller_link_0_3</child>
      <axis>
        <xyz>0 0 1</xyz>
        <dynamics>
          <spring_reference>0</spring_reference>
          <spring_stiffness>0</spring_stiffness>
          <damping>0</damping>
          <friction>0.001</friction>
        </dynamics>
      </axis>
    </joint>
    <link name="roller_link_1_3">
      <pose>0.03535533905932737 -0.008 -0.03535533905932738 0 -5.497787143782138 0</pose>
      <inertial>
        <mass>0.03</mass>
        <inertia>
          <ixx>3.5027999999999997e-06</ixx>
          <ixy>0</ixy>
          <ixz>0</ixz>
          <iyy>3.5027999999999997e-06</iyy>
          <iyz>0</iyz>
          <izz>2.5055999999999998e-06</izz>
        </inertia>
      </inertial>
      <visual name="visual">
        <geometry>
          <cylinder>
            <radius>0.012</radius>
            <length>0.03</length>
          </cylinder>
        </geometry>
        <material>
          <script>
            <uri>file://media/materials/scripts/gazebo.material</uri>
            <name>Gazebo/Black</name>
          </script>
        </material>
      </visual>
      <collision name="collision">
        <geometry>
          <cylinder>
            <radius>0.012</radius>
            <length>0.03</length>
          </cylinder>
        </geometry>
        <surface>
          <friction>
            <ode>
              <mu>1</mu>
              <mu2>1</mu2>
              <fdir1>0 0 0</fdir1>
              <slip1>0</slip1>
              <slip2>0</slip2>
            </ode>
          </friction>
        </surface>
      </collision>
    </link>
    <joint name="omni_wheel_joint_1_3" type="revolute">
      <parent>rim_link</parent>
      <child>roller_link_1_3</child>
      <axis>
        <xyz>0 0 1</xyz>
        <dynamics>
          <spring_reference>0</spring_reference>
          <spring_stiffness>0</spring_stiffness>
          <damping>0</damping>
          <friction>0.001</friction>
        </dynamics>
      </axis>
    </joint>
    <!--<static>true</static>-->
  </model>
</sdf>
