<?xml version="1.0" ?>
<!-- =================================================================================== -->
<!-- |    This document was autogenerated by xacro from /home/robostep/nav2-sample/src/OpenBase/openbase_gazebo_models/models/omni4/model.sdf.xacro | -->
<!-- |    EDITING THIS FILE BY HAND IS NOT RECOMMENDED                                 | -->
<!-- =================================================================================== -->
<sdf version="1.7">
  <model name="omni4_model">
    <pose>0 0 0.2 0 0 0</pose>
    <link name="body_link">
      <inertial>
        <mass>4.0</mass>
        <inertia>
          <ixx>0.0984</ixx>
          <ixy>0</ixy>
          <ixz>0</ixz>
          <iyy>0.0984</iyy>
          <iyz>0</iyz>
          <izz>0.19440000000000002</izz>
        </inertia>
      </inertial>
      <visual name="visual">
        <geometry>
          <box>
            <size>0.54 0.54 0.06</size>
          </box>
        </geometry>
        <material>
          <script>
            <uri>file://media/materials/scripts/gazebo.material</uri>
            <name>Gazebo/Grey</name>
          </script>
        </material>
      </visual>
      <collision name="collision">
        <geometry>
          <box>
            <size>0.54 0.54 0.06</size>
          </box>
        </geometry>
      </collision>
    </link>
    <include>
      <name>simple_omni_wheel_front_left_model</name>
      <uri>model://primitive_omni_wheel</uri>
      <pose>0.27 0.27 0 0 0 2.356194490192345</pose>
    </include>
    <include>
      <name>simple_omni_wheel_back_left_model</name>
      <uri>model://primitive_omni_wheel</uri>
      <pose>-0.27 0.27 0 0 0 3.9269908169872414</pose>
    </include>
    <include>
      <name>simple_omni_wheel_back_right_model</name>
      <uri>model://primitive_omni_wheel</uri>
      <pose>-0.2700000000000001 -0.27 0 0 0 5.497787143782138</pose>
    </include>
    <include>
      <name>simple_omni_wheel_front_right_model</name>
      <uri>model://primitive_omni_wheel</uri>
      <pose>0.26999999999999996 -0.2700000000000001 0 0 0 0.7853981633974483</pose>
    </include>
    <joint name="front_left_linear_joint" type="fixed">
      <parent>body_link</parent>
      <child>front_left_wheel_base_link</child>
      <axis>
        <limit>
          <lower>-0.1</lower>
          <upper>0.1</upper>
        </limit>
        <dynamics>
          <spring_reference>0.0</spring_reference>
          <spring_stiffness>2000.0</spring_stiffness>
          <damping>5.0</damping>
        </dynamics>
        <xyz>0 0 1</xyz>
      </axis>
      <physics>
        <ode>
          <implicit_spring_damper>true</implicit_spring_damper>
        </ode>
      </physics>
    </joint>
    <link name="front_left_wheel_base_link">
      <inertial>
        <mass>0.1</mass>
        <inertia>
          <ixx>0.0002</ixx>
          <ixy>0</ixy>
          <ixz>0</ixz>
          <iyy>0.0002</iyy>
          <iyz>0</iyz>
          <izz>0.0002</izz>
        </inertia>
      </inertial>
    </link>
    <joint name="front_left_rotational_joint" type="revolute">
      <parent>front_left_wheel_base_link</parent>
      <!--<parent>body_link</parent>-->
      <child>simple_omni_wheel_front_left_model::rim_link</child>
      <axis>
        <xyz>0 0 1</xyz>
        <dynamics>
          <spring_reference>0</spring_reference>
          <spring_stiffness>0</spring_stiffness>
          <damping>0</damping>
          <friction>0.0001</friction>
        </dynamics>
      </axis>
      <physics>
        <ode>
          <limit>
            <cfm>0</cfm>
            <erp>0.2</erp>
          </limit>
          <suspension>
            <cfm>0</cfm>
            <erp>0.2</erp>
          </suspension>
        </ode>
      </physics>
    </joint>
    <joint name="front_right_linear_joint" type="fixed">
      <parent>body_link</parent>
      <child>front_right_wheel_base_link</child>
      <axis>
        <limit>
          <lower>-0.1</lower>
          <upper>0.1</upper>
        </limit>
        <dynamics>
          <spring_reference>0.0</spring_reference>
          <spring_stiffness>2000.0</spring_stiffness>
          <damping>5.0</damping>
        </dynamics>
        <xyz>0 0 1</xyz>
      </axis>
      <physics>
        <ode>
          <implicit_spring_damper>true</implicit_spring_damper>
        </ode>
      </physics>
    </joint>
    <link name="front_right_wheel_base_link">
      <inertial>
        <mass>0.1</mass>
        <inertia>
          <ixx>0.0002</ixx>
          <ixy>0</ixy>
          <ixz>0</ixz>
          <iyy>0.0002</iyy>
          <iyz>0</iyz>
          <izz>0.0002</izz>
        </inertia>
      </inertial>
    </link>
    <joint name="front_right_rotational_joint" type="revolute">
      <parent>front_right_wheel_base_link</parent>
      <!--<parent>body_link</parent>-->
      <child>simple_omni_wheel_front_right_model::rim_link</child>
      <axis>
        <xyz>0 0 1</xyz>
        <dynamics>
          <spring_reference>0</spring_reference>
          <spring_stiffness>0</spring_stiffness>
          <damping>0</damping>
          <friction>0.0001</friction>
        </dynamics>
      </axis>
      <physics>
        <ode>
          <limit>
            <cfm>0</cfm>
            <erp>0.2</erp>
          </limit>
          <suspension>
            <cfm>0</cfm>
            <erp>0.2</erp>
          </suspension>
        </ode>
      </physics>
    </joint>
    <joint name="back_left_linear_joint" type="fixed">
      <parent>body_link</parent>
      <child>back_left_wheel_base_link</child>
      <axis>
        <limit>
          <lower>-0.1</lower>
          <upper>0.1</upper>
        </limit>
        <dynamics>
          <spring_reference>0.0</spring_reference>
          <spring_stiffness>2000.0</spring_stiffness>
          <damping>5.0</damping>
        </dynamics>
        <xyz>0 0 1</xyz>
      </axis>
      <physics>
        <ode>
          <implicit_spring_damper>true</implicit_spring_damper>
        </ode>
      </physics>
    </joint>
    <link name="back_left_wheel_base_link">
      <inertial>
        <mass>0.1</mass>
        <inertia>
          <ixx>0.0002</ixx>
          <ixy>0</ixy>
          <ixz>0</ixz>
          <iyy>0.0002</iyy>
          <iyz>0</iyz>
          <izz>0.0002</izz>
        </inertia>
      </inertial>
    </link>
    <joint name="back_left_rotational_joint" type="revolute">
      <parent>back_left_wheel_base_link</parent>
      <!--<parent>body_link</parent>-->
      <child>simple_omni_wheel_back_left_model::rim_link</child>
      <axis>
        <xyz>0 0 1</xyz>
        <dynamics>
          <spring_reference>0</spring_reference>
          <spring_stiffness>0</spring_stiffness>
          <damping>0</damping>
          <friction>0.0001</friction>
        </dynamics>
      </axis>
      <physics>
        <ode>
          <limit>
            <cfm>0</cfm>
            <erp>0.2</erp>
          </limit>
          <suspension>
            <cfm>0</cfm>
            <erp>0.2</erp>
          </suspension>
        </ode>
      </physics>
    </joint>
    <joint name="back_right_linear_joint" type="fixed">
      <parent>body_link</parent>
      <child>back_right_wheel_base_link</child>
      <axis>
        <limit>
          <lower>-0.1</lower>
          <upper>0.1</upper>
        </limit>
        <dynamics>
          <spring_reference>0.0</spring_reference>
          <spring_stiffness>2000.0</spring_stiffness>
          <damping>5.0</damping>
        </dynamics>
        <xyz>0 0 1</xyz>
      </axis>
      <physics>
        <ode>
          <implicit_spring_damper>true</implicit_spring_damper>
        </ode>
      </physics>
    </joint>
    <link name="back_right_wheel_base_link">
      <inertial>
        <mass>0.1</mass>
        <inertia>
          <ixx>0.0002</ixx>
          <ixy>0</ixy>
          <ixz>0</ixz>
          <iyy>0.0002</iyy>
          <iyz>0</iyz>
          <izz>0.0002</izz>
        </inertia>
      </inertial>
    </link>
    <joint name="back_right_rotational_joint" type="revolute">
      <parent>back_right_wheel_base_link</parent>
      <!--<parent>body_link</parent>-->
      <child>simple_omni_wheel_back_right_model::rim_link</child>
      <axis>
        <xyz>0 0 1</xyz>
        <dynamics>
          <spring_reference>0</spring_reference>
          <spring_stiffness>0</spring_stiffness>
          <damping>0</damping>
          <friction>0.0001</friction>
        </dynamics>
      </axis>
      <physics>
        <ode>
          <limit>
            <cfm>0</cfm>
            <erp>0.2</erp>
          </limit>
          <suspension>
            <cfm>0</cfm>
            <erp>0.2</erp>
          </suspension>
        </ode>
      </physics>
    </joint>
    <plugin filename="libgazebo_ros_omni_drive.so" name="omni_drive">
      <joint>front_left_rotational_joint</joint>
      <joint>front_right_rotational_joint</joint>
      <joint>back_left_rotational_joint</joint>
      <joint>back_right_rotational_joint</joint>
      <wheel_radius>0.06</wheel_radius>
    </plugin>
  </model>
</sdf>
