<?xml version="1.0" ?>
<!-- =================================================================================== -->
<!-- |    This document was autogenerated by xacro from /home/robostep/nav2-sample/src/OpenBase/openbase_gazebo_models/models/simple_omni_wheel/model.sdf.xacro | -->
<!-- |    EDITING THIS FILE BY HAND IS NOT RECOMMENDED                                 | -->
<!-- =================================================================================== -->
<sdf version="1.7">
  <model name="simple_omni_wheel_model">
    <link name="omni_wheel_rim_link">
      <inertial>
        <pose>0 0 0 0 1.5707963267948966 0</pose>
        <mass>0.00835758</mass>
        <inertia>
          <ixx>6.63684e-07</ixx>
          <ixy>0</ixy>
          <ixz>0</ixz>
          <iyy>6.63684e-07</iyy>
          <iyz>0</iyz>
          <izz>9.40333e-07</izz>
        </inertia>
      </inertial>
      <visual name="visual">
        <pose>0 0 0 0 1.5707963267948966 0</pose>
        <geometry>
          <cylinder>
            <radius>0.018</radius>
            <length>0.01</length>
          </cylinder>
        </geometry>
        <material>
          <script>
            <uri>file://media/materials/scripts/gazebo.material</uri>
            <name>Gazebo/Grey</name>
          </script>
        </material>
      </visual>
      <collision name="collision">
        <pose>0 0 0 0 1.5707963267948966 0</pose>
        <geometry>
          <cylinder>
            <radius>0.018</radius>
            <length>0.01</length>
          </cylinder>
        </geometry>
        <surface>
          <friction>
            <ode>
              <mu>1</mu>
              <mu2>1</mu2>
              <fdir1>0 0 0</fdir1>
              <slip1>0</slip1>
              <slip2>0</slip2>
            </ode>
          </friction>
        </surface>
      </collision>
    </link>
    <link name="omni_wheel_roller_e_link">
      <pose>-0.0055 0.01355 0 0 -0 0</pose>
      <inertial>
        <mass>0.00313845</mass>
        <pose>0 0 0 0 0 0</pose>
        <inertia>
          <ixx>2.53776e-07</ixx>
          <ixy>0</ixy>
          <ixz>0</ixz>
          <iyy>2.53776e-07</iyy>
          <iyz>0</iyz>
          <izz>1.47666e-07</izz>
        </inertia>
      </inertial>
      <visual name="visual">
        <pose>0 0 0 0 0 0</pose>
        <geometry>
          <cylinder>
            <radius>0.0049</radius>
            <length>0.01</length>
          </cylinder>
        </geometry>
        <material>
          <script>
            <uri>file://media/materials/scripts/gazebo.material</uri>
            <name>Gazebo/Black</name>
          </script>
        </material>
      </visual>
      <collision name="collision">
        <pose>0 0 0 0 0 0</pose>
        <geometry>
          <cylinder>
            <radius>0.0049</radius>
            <length>0.01</length>
          </cylinder>
        </geometry>
        <surface>
          <friction>
            <ode>
              <mu>1</mu>
              <mu2>1</mu2>
              <fdir1>0 0 0</fdir1>
              <slip1>0</slip1>
              <slip2>0</slip2>
            </ode>
          </friction>
        </surface>
      </collision>
    </link>
    <link name="omni_wheel_roller_n_link">
      <pose>-0.0055 0 0.01355 1.5707963267948966 -0 0</pose>
      <inertial>
        <mass>0.00313845</mass>
        <pose>0 0 0 0 0 0</pose>
        <inertia>
          <ixx>2.53776e-07</ixx>
          <ixy>0</ixy>
          <ixz>0</ixz>
          <iyy>2.53776e-07</iyy>
          <iyz>0</iyz>
          <izz>1.47666e-07</izz>
        </inertia>
      </inertial>
      <visual name="visual">
        <pose>0 0 0 0 0 0</pose>
        <geometry>
          <cylinder>
            <radius>0.0049</radius>
            <length>0.01</length>
          </cylinder>
        </geometry>
        <material>
          <script>
            <uri>file://media/materials/scripts/gazebo.material</uri>
            <name>Gazebo/Black</name>
          </script>
        </material>
      </visual>
      <collision name="collision">
        <pose>0 0 0 0 0 0</pose>
        <geometry>
          <cylinder>
            <radius>0.0049</radius>
            <length>0.01</length>
          </cylinder>
        </geometry>
        <surface>
          <friction>
            <ode>
              <mu>1</mu>
              <mu2>1</mu2>
              <fdir1>0 0 0</fdir1>
              <slip1>0</slip1>
              <slip2>0</slip2>
            </ode>
          </friction>
        </surface>
      </collision>
    </link>
    <link name="omni_wheel_roller_w_link">
      <pose>-0.0055 -0.01355 0 -3.141592653589793 0 0</pose>
      <inertial>
        <mass>0.00313845</mass>
        <pose>0 0 0 0 0 0</pose>
        <inertia>
          <ixx>2.53776e-07</ixx>
          <ixy>0</ixy>
          <ixz>0</ixz>
          <iyy>2.53776e-07</iyy>
          <iyz>0</iyz>
          <izz>1.47666e-07</izz>
        </inertia>
      </inertial>
      <visual name="visual">
        <pose>0 0 0 0 0 0</pose>
        <geometry>
          <cylinder>
            <radius>0.0049</radius>
            <length>0.01</length>
          </cylinder>
        </geometry>
        <material>
          <script>
            <uri>file://media/materials/scripts/gazebo.material</uri>
            <name>Gazebo/Black</name>
          </script>
        </material>
      </visual>
      <collision name="collision">
        <pose>0 0 0 0 0 0</pose>
        <geometry>
          <cylinder>
            <radius>0.0049</radius>
            <length>0.01</length>
          </cylinder>
        </geometry>
        <surface>
          <friction>
            <ode>
              <mu>1</mu>
              <mu2>1</mu2>
              <fdir1>0 0 0</fdir1>
              <slip1>0</slip1>
              <slip2>0</slip2>
            </ode>
          </friction>
        </surface>
      </collision>
    </link>
    <link name="omni_wheel_roller_s_link">
      <pose>-0.0055 0 -0.01355 -1.5707963267948966 0 0</pose>
      <inertial>
        <mass>0.00313845</mass>
        <pose>0 0 0 0 0 0</pose>
        <inertia>
          <ixx>2.53776e-07</ixx>
          <ixy>0</ixy>
          <ixz>0</ixz>
          <iyy>2.53776e-07</iyy>
          <iyz>0</iyz>
          <izz>1.47666e-07</izz>
        </inertia>
      </inertial>
      <visual name="visual">
        <pose>0 0 0 0 0 0</pose>
        <geometry>
          <cylinder>
            <radius>0.0049</radius>
            <length>0.01</length>
          </cylinder>
        </geometry>
        <material>
          <script>
            <uri>file://media/materials/scripts/gazebo.material</uri>
            <name>Gazebo/Black</name>
          </script>
        </material>
      </visual>
      <collision name="collision">
        <pose>0 0 0 0 0 0</pose>
        <geometry>
          <cylinder>
            <radius>0.0049</radius>
            <length>0.01</length>
          </cylinder>
        </geometry>
        <surface>
          <friction>
            <ode>
              <mu>1</mu>
              <mu2>1</mu2>
              <fdir1>0 0 0</fdir1>
              <slip1>0</slip1>
              <slip2>0</slip2>
            </ode>
          </friction>
        </surface>
      </collision>
    </link>
    <link name="omni_wheel_roller_ne_link">
      <pose>0.0055 0.009581 0.009581 0.7853981633974483 -0 0</pose>
      <inertial>
        <mass>0.00313845</mass>
        <pose>0 0 0 0 0 0</pose>
        <inertia>
          <ixx>2.53776e-07</ixx>
          <ixy>0</ixy>
          <ixz>0</ixz>
          <iyy>2.53776e-07</iyy>
          <iyz>0</iyz>
          <izz>1.47666e-07</izz>
        </inertia>
      </inertial>
      <visual name="visual">
        <pose>0 0 0 0 0 0</pose>
        <geometry>
          <cylinder>
            <radius>0.0049</radius>
            <length>0.01</length>
          </cylinder>
        </geometry>
        <material>
          <script>
            <uri>file://media/materials/scripts/gazebo.material</uri>
            <name>Gazebo/Black</name>
          </script>
        </material>
      </visual>
      <collision name="collision">
        <pose>0 0 0 0 0 0</pose>
        <geometry>
          <cylinder>
            <radius>0.0049</radius>
            <length>0.01</length>
          </cylinder>
        </geometry>
        <surface>
          <friction>
            <ode>
              <mu>1</mu>
              <mu2>1</mu2>
              <fdir1>0 0 0</fdir1>
              <slip1>0</slip1>
              <slip2>0</slip2>
            </ode>
          </friction>
        </surface>
      </collision>
    </link>
    <link name="omni_wheel_roller_nw_link">
      <pose>0.0055 -0.009581 0.009581 2.356194490192345 -0 0</pose>
      <inertial>
        <mass>0.00313845</mass>
        <pose>0 0 0 0 0 0</pose>
        <inertia>
          <ixx>2.53776e-07</ixx>
          <ixy>0</ixy>
          <ixz>0</ixz>
          <iyy>2.53776e-07</iyy>
          <iyz>0</iyz>
          <izz>1.47666e-07</izz>
        </inertia>
      </inertial>
      <visual name="visual">
        <pose>0 0 0 0 0 0</pose>
        <geometry>
          <cylinder>
            <radius>0.0049</radius>
            <length>0.01</length>
          </cylinder>
        </geometry>
        <material>
          <script>
            <uri>file://media/materials/scripts/gazebo.material</uri>
            <name>Gazebo/Black</name>
          </script>
        </material>
      </visual>
      <collision name="collision">
        <pose>0 0 0 0 0 0</pose>
        <geometry>
          <cylinder>
            <radius>0.0049</radius>
            <length>0.01</length>
          </cylinder>
        </geometry>
        <surface>
          <friction>
            <ode>
              <mu>1</mu>
              <mu2>1</mu2>
              <fdir1>0 0 0</fdir1>
              <slip1>0</slip1>
              <slip2>0</slip2>
            </ode>
          </friction>
        </surface>
      </collision>
    </link>
    <link name="omni_wheel_roller_sw_link">
      <pose>0.0055 -0.009581 -0.009581 -2.356194490192345 0 0</pose>
      <inertial>
        <mass>0.00313845</mass>
        <pose>0 0 0 0 0 0</pose>
        <inertia>
          <ixx>2.53776e-07</ixx>
          <ixy>0</ixy>
          <ixz>0</ixz>
          <iyy>2.53776e-07</iyy>
          <iyz>0</iyz>
          <izz>1.47666e-07</izz>
        </inertia>
      </inertial>
      <visual name="visual">
        <pose>0 0 0 0 0 0</pose>
        <geometry>
          <cylinder>
            <radius>0.0049</radius>
            <length>0.01</length>
          </cylinder>
        </geometry>
        <material>
          <script>
            <uri>file://media/materials/scripts/gazebo.material</uri>
            <name>Gazebo/Black</name>
          </script>
        </material>
      </visual>
      <collision name="collision">
        <pose>0 0 0 0 0 0</pose>
        <geometry>
          <cylinder>
            <radius>0.0049</radius>
            <length>0.01</length>
          </cylinder>
        </geometry>
        <surface>
          <friction>
            <ode>
              <mu>1</mu>
              <mu2>1</mu2>
              <fdir1>0 0 0</fdir1>
              <slip1>0</slip1>
              <slip2>0</slip2>
            </ode>
          </friction>
        </surface>
      </collision>
    </link>
    <link name="omni_wheel_roller_se_link">
      <pose>0.0055 0.009581 -0.009581 -0.7853981633974483 0 0</pose>
      <inertial>
        <mass>0.00313845</mass>
        <pose>0 0 0 0 0 0</pose>
        <inertia>
          <ixx>2.53776e-07</ixx>
          <ixy>0</ixy>
          <ixz>0</ixz>
          <iyy>2.53776e-07</iyy>
          <iyz>0</iyz>
          <izz>1.47666e-07</izz>
        </inertia>
      </inertial>
      <visual name="visual">
        <pose>0 0 0 0 0 0</pose>
        <geometry>
          <cylinder>
            <radius>0.0049</radius>
            <length>0.01</length>
          </cylinder>
        </geometry>
        <material>
          <script>
            <uri>file://media/materials/scripts/gazebo.material</uri>
            <name>Gazebo/Black</name>
          </script>
        </material>
      </visual>
      <collision name="collision">
        <pose>0 0 0 0 0 0</pose>
        <geometry>
          <cylinder>
            <radius>0.0049</radius>
            <length>0.01</length>
          </cylinder>
        </geometry>
        <surface>
          <friction>
            <ode>
              <mu>1</mu>
              <mu2>1</mu2>
              <fdir1>0 0 0</fdir1>
              <slip1>0</slip1>
              <slip2>0</slip2>
            </ode>
          </friction>
        </surface>
      </collision>
    </link>
    <joint name="omni_wheel_s_joint" type="revolute">
      <parent>omni_wheel_rim_link</parent>
      <child>omni_wheel_roller_s_link</child>
      <pose>0 0 0 0 0 1.5707963267948966</pose>
      <axis>
        <xyz>0 0 1</xyz>
        <dynamics>
          <spring_reference>0</spring_reference>
          <spring_stiffness>0</spring_stiffness>
          <damping>0</damping>
          <friction>0.001</friction>
        </dynamics>
      </axis>
    </joint>
    <joint name="omni_wheel_se_joint" type="revolute">
      <parent>omni_wheel_rim_link</parent>
      <child>omni_wheel_roller_se_link</child>
      <pose>0 0 0 0 0 1.5707963267948966</pose>
      <axis>
        <xyz>0 0 1</xyz>
        <dynamics>
          <spring_reference>0</spring_reference>
          <spring_stiffness>0</spring_stiffness>
          <damping>0</damping>
          <friction>0.001</friction>
        </dynamics>
      </axis>
    </joint>
    <joint name="omni_wheel_e_joint" type="revolute">
      <parent>omni_wheel_rim_link</parent>
      <child>omni_wheel_roller_e_link</child>
      <pose>0 0 0 0 0 1.5707963267948966</pose>
      <axis>
        <xyz>0 0 1</xyz>
        <dynamics>
          <spring_reference>0</spring_reference>
          <spring_stiffness>0</spring_stiffness>
          <damping>0</damping>
          <friction>0.001</friction>
        </dynamics>
      </axis>
    </joint>
    <joint name="omni_wheel_ne_joint" type="revolute">
      <parent>omni_wheel_rim_link</parent>
      <child>omni_wheel_roller_ne_link</child>
      <pose>0 0 0 0 0 1.5707963267948966</pose>
      <axis>
        <xyz>0 0 1</xyz>
        <dynamics>
          <spring_reference>0</spring_reference>
          <spring_stiffness>0</spring_stiffness>
          <damping>0</damping>
          <friction>0.001</friction>
        </dynamics>
      </axis>
    </joint>
    <joint name="omni_wheel_n_joint" type="revolute">
      <parent>omni_wheel_rim_link</parent>
      <child>omni_wheel_roller_n_link</child>
      <pose>0 0 0 0 0 1.5707963267948966</pose>
      <axis>
        <xyz>0 0 1</xyz>
        <dynamics>
          <spring_reference>0</spring_reference>
          <spring_stiffness>0</spring_stiffness>
          <damping>0</damping>
          <friction>0.001</friction>
        </dynamics>
      </axis>
    </joint>
    <joint name="omni_wheel_nw_joint" type="revolute">
      <parent>omni_wheel_rim_link</parent>
      <child>omni_wheel_roller_nw_link</child>
      <pose>0 0 0 0 0 1.5707963267948966</pose>
      <axis>
        <xyz>0 0 1</xyz>
        <dynamics>
          <spring_reference>0</spring_reference>
          <spring_stiffness>0</spring_stiffness>
          <damping>0</damping>
          <friction>0.001</friction>
        </dynamics>
      </axis>
    </joint>
    <joint name="omni_wheel_w_joint" type="revolute">
      <parent>omni_wheel_rim_link</parent>
      <child>omni_wheel_roller_w_link</child>
      <pose>0 0 0 0 0 1.5707963267948966</pose>
      <axis>
        <xyz>0 0 1</xyz>
        <dynamics>
          <spring_reference>0</spring_reference>
          <spring_stiffness>0</spring_stiffness>
          <damping>0</damping>
          <friction>0.001</friction>
        </dynamics>
      </axis>
    </joint>
    <joint name="omni_wheel_sw_joint" type="revolute">
      <parent>omni_wheel_rim_link</parent>
      <child>omni_wheel_roller_sw_link</child>
      <pose>0 0 0 0 0 1.5707963267948966</pose>
      <axis>
        <xyz>0 0 1</xyz>
        <dynamics>
          <spring_reference>0</spring_reference>
          <spring_stiffness>0</spring_stiffness>
          <damping>0</damping>
          <friction>0.001</friction>
        </dynamics>
      </axis>
    </joint>
  </model>
</sdf>
